Workbook
Name _xlchart.v1.11: 'Multiple Valuation'!$Q$8
Name _xlchart.v1.10: 'Multiple Valuation'!$Q$7
Name _xlchart.v1.16: 'Multiple Valuation'!$Q$21
Name _xlchart.v1.8: 'Multiple Valuation'!$Q$21
Name _xlchart.v1.19: 'Multiple Valuation'!$Q$8
Name _xlchart.v1.1: 'Multiple Valuation'!$Q$6
Name _xlchart.v1.17: 'Multiple Valuation'!$Q$6
Name _xlchart.v1.15: 'Multiple Valuation'!$Q$8
Name _xlchart.v1.13: 'Multiple Valuation'!$Q$6
Name _xlchart.v1.6: 'Multiple Valuation'!$Q$7
Name _xlchart.v1.5: 'Multiple Valuation'!$Q$6
Name _xlchart.v1.3: 'Multiple Valuation'!$Q$8
Name _xlchart.v1.14: 'Multiple Valuation'!$Q$7
Name _xlchart.v1.7: 'Multiple Valuation'!$Q$8
Name _xlchart.v1.18: 'Multiple Valuation'!$Q$7
Name _xlchart.v1.0: 'Multiple Valuation'!$Q$21
Name _xlchart.v1.9: 'Multiple Valuation'!$Q$6
Name _xlchart.v1.12: 'Multiple Valuation'!$Q$21
Name _xlchart.v1.2: 'Multiple Valuation'!$Q$7
Name _xlchart.v1.4: 'Multiple Valuation'!$Q$21

Sheet Multiple Valuation
B2: Amount in thousands | N2: Currency in USD
B3: Comparable Company Valuation
B4: Company | C4: Market Data | I4: Financials | N4: Valuation
C5: Share Price | D5: Outstanding Shares | E5: Equity Value | F5: Net Debt | G5: Enterprise Value | I5: Revenue | J5: Earnings per Share | K5: Net Income | L5: EBIDTA | N5: EV/Revenue | O5: EV/EBIDTA | P5: Equity Value / Net Income | Q5: P/E
B6: Honda | C6: =Data!D3 -> 28.55 | D6: =Data!E3 -> 4828907.4 | E6: =C6*D6 -> 1.3786531e+08 | F6: =Data!I3 -> 37377769 | G6: =E6+F6 -> 1.7524308e+08 | I6: =Data!K3 -> 1.3707166e+08 | J6: =Data!L3 -> 3.89 | K6: 6293340.5 | L6: =Data!M3 -> 14946679 | N6: =G6/I6 -> 1.2784778 | O6: =G6/L6 -> 11.724549 | P6: =E6/K6 -> 21.906538 | Q6: =C6/J6 -> 7.3393316
B7: Mitsubishi | C7: =Data!D4 -> 3.55 | D7: =Data!E4 -> 1486808.3 | E7: =C7*D7 -> 5278169.5 | F7: =Data!I4 -> -1153278.9 | G7: =E7+F7 -> 4124890.6 | I7: =Data!K4 -> 17688541 | J7: =Data!L4 -> 0.72 | K7: 987905.72 | L7: =Data!M4 -> 1614542.2 | N7: =G7/I7 -> 0.23319564 | O7: =G7/L7 -> 2.5548359 | P7: =E7/K7 -> 5.3427866 | Q7: =C7/J7 -> 4.9305556
B8: Nissan | C8: =Data!D5 -> 6.08 | D8: =Data!E5 -> 3740203.2 | E8: =C8*D8 -> 22740435 | F8: =Data!I5 -> 36011610 | G8: =E8+F8 -> 58752045 | I8: =Data!K5 -> 80439019 | J8: =Data!L5 -> 1.4 | K8: 2724398.6 | L8: =Data!M5 -> 8346245.5 | N8: =G8/I8 -> 0.73039236 | O8: =G8/L8 -> 7.0393382 | P8: =E8/K8 -> 8.3469559 | Q8: =C8/J8 -> 4.3428571
B9: Toyota | C9: =Data!D6 -> 194.61 | D9: =Data!E6 -> 13474172 | E9: =C9*D9 -> 2622208619 | F9: =Data!I6 -> 142337977 | G9: =E9+F9 -> 2764546596 | I9: =Data!K6 -> 2.9419399e+08 | J9: 25.25 | K9: 27219261 | L9: =Data!M6 -> 53547899 | N9: =G9/I9 -> 9.3970192 | O9: =G9/L9 -> 51.627545 | P9: =E9/K9 -> 96.336509 | Q9: =C9/J9 -> 7.7073267
B10: Volkswagen | C10: =Data!D7 -> 95.09 | D10: =Data!E7 -> 501295.26 | E10: =C10*D10 -> 47668166 | F10: =Data!I7 -> 1.2285523e+08 | G10: =E10+F10 -> 1.7052339e+08 | I10: =Data!K7 -> 3.3480446e+08 | J10: =Data!L7 -> 25.2 | K10: 13427054 | L10: =Data!M7 -> 54369002 | N10: =G10/I10 -> 0.50932235 | O10: =G10/L10 -> 3.1364084 | P10: =E10/K10 -> 3.5501582 | Q10: =C10/J10 -> 3.7734127
B11: BYD | C11: =Data!D8 -> 34 | D11: =Data!E8 -> 2909265.9 | E11: =C11*D11 -> 98915039 | F11: =Data!I8 -> -5777396.8 | G11: =E11+F11 -> 93137642 | I11: =Data!K8 -> 93103698 | J11: =Data!L8 -> 1.59 | K11: 4637035.3 | L11: =Data!M8 -> 6096272.8 | N11: =G11/I11 -> 1.0003646 | O11: =G11/L11 -> 15.277801 | P11: =E11/K11 -> 21.331526 | Q11: =C11/J11 -> 21.383648
B12: General Motors | C12: =Data!D9 -> 53.27 | D12: =Data!E9 -> 1200000 | E12: =C12*D12 -> 63924000 | F12: =Data!I9 -> 96182000 | G12: =E12+F12 -> 160106000 | I12: =Data!K9 -> 182719000 | J12: =Data!L9 -> 9.46 | K12: 11070000 | L12: =Data!M9 -> 25371000 | N12: =G12/I12 -> 0.87624166 | O12: =G12/L12 -> 6.3105908 | P12: =E12/K12 -> 5.7745257 | Q12: =C12/J12 -> 5.6310782
B13: Ford | C13: =Data!D10 -> 9.9 | D13: =Data!E10 -> 3999960.1 | E13: =C13*D13 -> 39599605 | F13: =Data!I10 -> 133532000 | G13: =E13+F13 -> 1.7313161e+08 | I13: =Data!K10 -> 46196000 | J13: =Data!L4 -> 0.72 | K13: 3529000 | L13: =Data!M10 -> 10381000 | N13: =G13/I13 -> 3.7477618 | O13: =G13/L13 -> 16.677739 | P13: =E13/K13 -> 11.221197 | Q13: =C13/J13 -> 13.75
B14: SAIC | C14: =Data!D11 -> 2.83 | D14: =Data!E11 -> 11575299 | E14: =C14*D14 -> 32758097 | F14: =Data!I11 -> -6831998.9 | G14: =E14+F14 -> 25926099 | I14: =Data!K11 -> 88949062 | J14: =Data!L11 -> 0.84 | K14: 1313546.1 | L14: =Data!M11 -> 2538120.2 | N14: =G14/I14 -> 0.2914713 | O14: =G14/L14 -> 10.214685 | P14: =E14/K14 -> 24.938673 | Q14: =C14/J14 -> 3.3690476
B15: Tesla | C15: =Data!D12 -> 403.84 | D15: =Data!E12 -> 3207000 | E15: =C15*D15 -> 1295114880 | F15: =Data!I12 -> -20865000 | G15: =E15+F15 -> 1274249880 | I15: =Data!K12 -> 97150000 | J15: =Data!L12 -> 4.01 | K15: 12704000 | L15: =Data!M12 -> 13834000 | N15: =G15/I15 -> 13.116314 | O15: =G15/L15 -> 92.11001 | P15: =E15/K15 -> 101.94544 | Q15: =C15/J15 -> 100.70823
B16: High | N16: =MAX(N6:N15) -> 13.116314 | O16: =MAX(O6:O15) -> 92.11001 | P16: =MAX(P6:P15) -> 101.94544 | Q16: =MAX(Q6:Q15) -> 100.70823
B17: 75th Percentile | N17: =QUARTILE(N6:N15,3) -> 3.1304408 | O17: =QUARTILE(O6:O15,3) -> 16.327754 | P17: =QUARTILE(P6:P15,3) -> 24.18064 | Q17: =QUARTILE(Q6:Q15,3) -> 12.239332
B18: 50th Percentile | N18: =QUARTILE(N6:N15,2) -> 0.93830313 | O18: =QUARTILE(O6:O15,2) -> 10.969617 | P18: =QUARTILE(P6:P15,2) -> 16.276362 | Q18: =QUARTILE(Q6:Q15,2) -> 6.4852049
B19: 25th Percentile | N19: =QUARTILE(N6:N15,1) -> 0.56458985 | O19: =QUARTILE(O6:O15,1) -> 6.4927777 | P19: =QUARTILE(P6:P15,1) -> 6.4176333 | Q19: =QUARTILE(Q6:Q15,1) -> 4.4897817
B20: Average | N20: =AVERAGE(N6:N15) -> 3.118056 | O20: =AVERAGE(O6:O15) -> 21.66735 | P20: =AVERAGE(P6:P15) -> 30.069431 | Q20: =AVERAGE(Q6:Q15) -> 17.293549
B21: Median | N21: =MEDIAN(N6:N15) -> 0.93830313 | O21: =MEDIAN(O6:O15) -> 10.969617 | P21: =MEDIAN(P6:P15) -> 16.276362 | Q21: =MEDIAN(Q6:Q15) -> 6.4852049
B22: Low | N22: =MIN(N6:N15) -> 0.23319564 | O22: =MIN(O6:O15) -> 2.5548359 | P22: =MIN(P6:P15) -> 3.5501582 | Q22: =MIN(Q6:Q15) -> 3.3690476
B24: Honda Comparable Valuation
B26: Implied Enterprise Value | N26: =N21*I6 -> 1.2861477e+08 | O26: =O21*L6 -> 1.6395935e+08 | P26: =+P28+P27 -> 1.3981046e+08
B27: Net Debt | N27: =F6 -> 37377769 | O27: =F6 -> 37377769 | P27: =F6 -> 37377769
B28: Implied Market Value | N28: =N26-N27 -> 91236997 | O28: =O26-O27 -> 126581578 | P28: =P21*K6 -> 1.0243269e+08
B29: Shares Outstanding | N29: =D6 -> 4828907.4 | O29: =D6 -> 4828907.4 | P29: =D6 -> 4828907.4
B31: Implied Value per Share | N31: =N28/N29 -> 18.893921 | O31: =O28/O29 -> 26.213296 | P31: =P28/P29 -> 21.212394 | Q31: =Q21*J6 -> 25.227447
N33: =IF(N31>$D$7,"Undervalued","Overvalued") -> Overvalued | O33: =IF(O31>$D$7,"Undervalued","Overvalued") -> Overvalued | P33: =IF(P31>$D$7,"Undervalued","Overvalued") -> Overvalued | Q33: =IF(Q31>$D$7,"Undervalued","Overvalued") -> Overvalued
B35: Mitsubishi Comparable Valuation
B37: Implied Enterprise Value | N37: =N21*I7 -> 16597213 | O37: =O21*L7 -> 17710910 | P37: =+P39+P38 -> 14926232
B38: Net Debt | N38: =F7 -> -1153278.9 | O38: =F7 -> -1153278.9 | P38: =F7 -> -1153278.9
B39: Implied Market Value | N39: =N37-N38 -> 17750492 | O39: =O37-O38 -> 18864189 | P39: =P21*K7 -> 16079511
B40: Shares Outstanding | N40: =D7 -> 1486808.3 | O40: =D7 -> 1486808.3 | P40: =D7 -> 1486808.3
B42: Implied Value per Share | N42: =N39/N40 -> 11.938655 | O42: =O39/O40 -> 12.687708 | P42: =P39/P40 -> 10.814784 | Q42: =Q21*J7 -> 4.6693475
N44: Undervalued | O44: Undervalued | P44: Undervalued | Q44: Undervalued
B46: Nissan Comparable Valuation
B48: Implied Enterprise Value | N48: =N21*I8 -> 75476183 | O48: =O21*L8 -> 91555117 | P48: =+P50+P49 -> 80354908
B49: Net Debt | N49: =F8 -> 36011610 | O49: =F8 -> 36011610 | P49: =F8 -> 36011610
B50: Implied Market Value | N50: =N48-N49 -> 39464573 | O50: =O48-O49 -> 55543507 | P50: =P21*K8 -> 44343298
B51: Shares Outstanding | N51: =D8 -> 3740203.2 | O51: =D8 -> 3740203.2 | P51: =D8 -> 3740203.2
...

Sheet Data
B1: All numbers in thousands | J1: Currency in USD
B2: S.No. | C2: Company | D2: Share Price | E2: Outstanding Shares | F2: Market Capitalization | G2: Total Debt | H2: Cash & Cash Equivalents | I2: Net Debt | J2: Enterprise Value | K2: Total Revenue | L2: Earnings per Share | M2: EBITDA
B3: 1 | C3: Honda | D3: 28.55 | E3: 4828907.4 | F3: =D3*E3 -> 1.3786531e+08 | G3: 70250000 | H3: 32872231 | I3: =G3-H3 -> 37377769 | J3: =F3+G3-H3 -> 1.7524308e+08 | K3: 1.3707166e+08 | L3: 3.89 | M3: 14946679
B4: 2 | C4: Mitsubishi | D4: 3.55 | E4: 1486808.3 | F4: =D4*E4 -> 5278169.5 | G4: 3121980.1 | H4: 4275259 | I4: =G4-H4 -> -1153278.9 | J4: =F4+G4-H4 -> 4124890.6 | K4: 17688541 | L4: 0.72 | M4: 1614542.2
B5: 3 | C5: Nissan | D5: 6.08 | E5: 3740203.2 | F5: =D5*E5 -> 22740435 | G5: 49531362 | H5: 13519752 | I5: =G5-H5 -> 36011610 | J5: =F5+G5-H5 -> 58752045 | K5: 80439019 | L5: 1.4 | M5: 8346245.5
B6: 4 | C6: Toyota | D6: 194.61 | E6: 13474172 | F6: =D6*E6 -> 2622208619 | G6: 2.3183507e+08 | H6: 89497090 | I6: =G6-H6 -> 142337977 | J6: =F6+G6-H6 -> 2764546596 | K6: 2.9419399e+08 | L6: 0.27 | M6: 53547899
B7: 5 | C7: Volkswagen | D7: 95.09 | E7: 501295.26 | F7: =D7*E7 -> 47668166 | G7: 2.0015685e+08 | H7: 77301620 | I7: =G7-H7 -> 1.2285523e+08 | J7: =F7+G7-H7 -> 1.7052339e+08 | K7: 3.3480446e+08 | L7: 25.2 | M7: 54369002
B8: 6 | C8: BYD | D8: 34 | E8: 2909265.9 | F8: =D8*E8 -> 98915039 | G8: 6740447.8 | H8: 12517845 | I8: =G8-H8 -> -5777396.8 | J8: =F8+G8-H8 -> 93137642 | K8: 93103698 | L8: 1.59 | M8: 6096272.8
B9: 7 | C9: General Motors | D9: 53.27 | E9: 1200000 | F9: =D9*E9 -> 63924000 | G9: 122648000 | H9: 26466000 | I9: =G9-H9 -> 96182000 | J9: =F9+G9-H9 -> 160106000 | K9: 182719000 | L9: 9.46 | M9: 25371000
B10: 8 | C10: Ford | D10: 9.9 | E10: 3999960.1 | F10: =D10*E10 -> 39599605 | G10: 157258000 | H10: 23726000 | I10: =G10-H10 -> 133532000 | J10: =F10+G10-H10 -> 1.7313161e+08 | K10: 46196000 | L10: 0.89 | M10: 10381000
B11: 9 | C11: SAIC | D11: 2.83 | E11: 11575299 | F11: =D11*E11 -> 32758097 | G11: 24275522 | H11: 31107521 | I11: =G11-H11 -> -6831998.9 | J11: =F11+G11-H11 -> 25926099 | K11: 88949062 | L11: 0.84 | M11: 2538120.2
B12: 10 | C12: Tesla | D12: 403.84 | E12: 3207000 | F12: =D12*E12 -> 1295114880 | G12: 12783000 | H12: 33648000 | I12: =G12-H12 -> -20865000 | J12: =F12+G12-H12 -> 1274249880 | K12: 97150000 | L12: 4.01 | M12: 13834000

Sheet Comparison
